<?xml version="1.0"?>
<robot xmlns:xacro="http://www.ros.org/wiki/xacro">

<xacro:macro name="mouth" params="parent xyz rpy">
    <joint name="mouth_joint" type="revolute">
        <axis xyz="0 -1 0"/>
        <!-- 2 SG90 servos working in parallel for the mouth -->
        <limit effort="0.49" velocity="15.7"
               upper="${10*3.14/180}" lower="${-60*3.14/180}"/>
        <origin xyz="${xyz}" rpy="${rpy}"/>
        <parent link="${parent}"/>
        <child link="mouth_link"/>
    </joint>

    <link name="mouth_link">
        <inertial>
            <origin xyz="${0.0785-0.026117} 0.0 ${-0.0075+0.004753}" 
                    rpy="0 0 1.57"/>
            <mass value="0.034405"/>
            <inertia ixx="2.688e-05" ixy="0.0" ixz="0.0"
                     iyy="9.225e-05" iyz="-2.827e-06" izz="1.179e-04"/>
        </inertial>
        <visual>
            <origin xyz="0.0785 0 -0.0075" rpy="0 0 1.57"/>
            <geometry>
                <mesh filename="$(find frea_description)/meshes/mouth.stl"/>
            </geometry>
        </visual>
        <collision>
            <origin xyz="0.0785 0 -0.0075" rpy="1.57 0 0"/>
            <geometry>
                <cylinder radius="0.003" length="0.1"/>
            </geometry>
        </collision>
        <collision>
            <origin xyz="${0.0785-0.04} 0.062 ${-0.0075+0.008}"
                    rpy="0 1.57 0"/>
            <geometry>
                <cylinder radius="0.003" length="0.06"/>
            </geometry>
        </collision>
        <collision>
            <origin xyz="${0.0785-0.04} -0.062 ${-0.0075+0.008}"
                    rpy="0 1.57 0"/>
            <geometry>
                <cylinder radius="0.003" length="0.06"/>
            </geometry>
        </collision>
    </link>

    <gazebo reference="mouth_link">
        <mu1>0.3</mu1>
        <mu2>0.3</mu2>
        <maxVel>0.0</maxVel>
        <minDepth>0.001</minDepth>
    </gazebo>

    <transmission name="mouth_transmission">
        <type>transmission_interface/SimpleTransmission</type>
        <joint name="mouth_joint">
            <hardwareInterface>hardware_interface/EffortJointInterface</hardwareInterface>
        </joint>
        <actuator name="mouth_motor">
            <hardwareInterface>hardware_interface/EffortJointInterface</hardwareInterface>
            <mechanicalReduction>1</mechanicalReduction>
        </actuator>
    </transmission>
</xacro:macro>

</robot>
