<?xml version="1.0"?>
<robot xmlns:xacro="http://www.ros.org/wiki/xacro">

<xacro:macro name="left_ear" params="parent xyz rpy">
    <joint name="left_ear_joint" type="revolute">
        <axis xyz="0 1 0"/>
        <!-- One SG90 Servo -->
        <limit effort="0.245" velocity="15.7"
               upper="${20*3.14/180}" lower="${-75*3.14/180}"/>
        <origin xyz="${xyz}" rpy="${rpy}"/>
        <parent link="${parent}"/>
        <child link="left_ear_link"/>
    </joint>

    <link name="left_ear_link">
        <inertial>
            <origin xyz="-0.002515 -0.001926 0.05596" rpy="1.57 -1.57 0"/>
            <mass value="0.016118"/>
            <inertia ixx="1.528e-06" ixy="2.682e-07" ixz="1.040e-08"
                     iyy="1.341e-05" iyz="-9.84e-10" izz="1.486e-05"/>
        </inertial>

        <visual>
           <origin xyz="0 0.0025 0" rpy="1.57 -1.57 0"/>
           <geometry>
                <mesh filename="$(find frea_description)/meshes/left_ear.stl"/>
            </geometry>
        </visual>

        <collision>
           <origin xyz="0.005 0 0.06" rpy="0 0 0"/>
            <geometry>
                <box size="0.04 0.005 0.12"/>
            </geometry>
        </collision>
    </link>

    <gazebo reference="left_ear_link">
        <mu1>0.2</mu1>
        <mu2>0.2</mu2>
        <maxVel>0.0</maxVel>
        <minDepth>0.001</minDepth>
    </gazebo>

    <transmission name="left_ear_transmission">
        <type>transmission_interface/SimpleTransmission</type>
        <joint name="left_ear_joint">
            <hardwareInterface>hardware_interface/EffortJointInterface</hardwareInterface>
        </joint>
        <actuator name="left_ear_motor">
            <hardwareInterface>hardware_interface/EffortJointInterface</hardwareInterface>
            <mechanicalReduction>1</mechanicalReduction>
        </actuator>
    </transmission>
</xacro:macro>

</robot>
