<?xml version="1.0"?>
<robot xmlns:xacro="http://www.ros.org/wiki/xacro">

<xacro:macro name="right_ear" params="parent xyz rpy">
    <joint name="right_ear_joint" type="revolute">
        <axis xyz="0 1 0"/>
        <!-- One SG90 Servo -->
        <limit effort="0.245" velocity="15.7"
               upper="${20*3.14/180}" lower="${-75*3.14/180}"/>
        <origin xyz="${xyz}" rpy="${rpy}"/>
        <parent link="${parent}"/>
        <child link="right_ear_link"/>
    </joint>

    <link name="right_ear_link">
        <inertial>
            <origin xyz="-0.002515 0.000906 0.054113" rpy="-1.57 -1.57 0"/>
            <mass value="0.01533"/>
            <inertia ixx="1.167e-06" ixy="3.845e-07" ixz="-9.99e-09"
                     iyy="1.284e-05" iyz="-3.57e-10" izz="1.394e-05"/>
        </inertial>

        <visual>
           <origin xyz="0 0.0025 0" rpy="-1.57 -1.57 0"/>
           <geometry>
                <mesh filename="$(find frea_description)/meshes/right_ear.stl"/>
            </geometry>
        </visual>

        <collision>
           <origin xyz="0 0 0.06" rpy="0 0 0"/>
            <geometry>
                <box size="0.03 0.005 0.12"/>
            </geometry>
        </collision>
    </link>

    <gazebo reference="right_ear_link">
        <mu1>0.2</mu1>
        <mu2>0.2</mu2>
        <maxVel>0.0</maxVel>
        <minDepth>0.001</minDepth>
    </gazebo>

    <transmission name="right_ear_transmission">
        <type>transmission_interface/SimpleTransmission</type>
        <joint name="right_ear_joint">
            <hardwareInterface>hardware_interface/EffortJointInterface</hardwareInterface>
        </joint>
        <actuator name="right_ear_motor">
            <hardwareInterface>hardware_interface/EffortJointInterface</hardwareInterface>
            <mechanicalReduction>1</mechanicalReduction>
        </actuator>
    </transmission>
</xacro:macro>

</robot>
